Workbook

Sheet Dashboard
B2: EC LAB — INVENTORY MANAGEMENT SYSTEM
B3: Live stock, bin locations and issue records for the EC Lab component racks.
B5: COMPONENTS | D5: UNITS ON SHELF | F5: LOW STOCK | H5: OUT OF STOCK | J5: ISSUED OUT | L5: NOT COUNTED
B6: =COUNTA(Inventory!$A$2:$A$381) -> 380 | D6: =SUM(Inventory!$H$2:$H$381) -> 6203 | F6: =COUNTIF(Inventory!$J$2:$J$381,"Low stock") -> 86 | H6: =COUNTIF(Inventory!$J$2:$J$381,"Out of stock") -> 20 | J6: =SUMIF('Issue Log'!$J$2:$J$501,"Out",'Issue Log'!$G$2:$G$501) -> 0 | L6: =COUNTIF(Inventory!$J$2:$J$381,"Not counted") -> 46
B7: distinct line items | D7: available pieces | F7: below minimum | H7: zero available | J7: pieces with students | L7: need a stock take
B9: STOCK BY CATEGORY | G9: HOW TO USE THIS WORKBOOK
B10: Category | C10: Items | D10: Low / Out | E10: Available units | G10: Search | H10: Type a component name in the yellow cell — it returns the exact bin (e.g. 1K Ω Resistor → A2).
B11: Antenna | C11: =COUNTIF(Inventory!$C$2:$C$381,$B11) -> 2 | D11: =COUNTIFS(Inventory!$C$2:$C$381,$B11,Inventory!$J$2:$J$381,"Low stock")+COUNTIFS(Inventory!$C$2:$C$381,$B11,Inventory!$J$2:$J$381,"Out of stock") -> 0 | E11: =SUMIF(Inventory!$C$2:$C$381,$B11,Inventory!$H$2:$H$381) -> 11 | G11: Inventory | H11: The master list. Edit only the blue columns: Stock Qty and Min. Rows colour themselves by status.
B12: Battery | C12: =COUNTIF(Inventory!$C$2:$C$381,$B12) -> 10 | D12: =COUNTIFS(Inventory!$C$2:$C$381,$B12,Inventory!$J$2:$J$381,"Low stock")+COUNTIFS(Inventory!$C$2:$C$381,$B12,Inventory!$J$2:$J$381,"Out of stock") -> 4 | E12: =SUMIF(Inventory!$C$2:$C$381,$B12,Inventory!$H$2:$H$381) -> 69 | G12: Low Stock | H12: Auto-built restocking list — everything out, below minimum, or never counted.
B13: Buzzer | C13: =COUNTIF(Inventory!$C$2:$C$381,$B13) -> 1 | D13: =COUNTIFS(Inventory!$C$2:$C$381,$B13,Inventory!$J$2:$J$381,"Low stock")+COUNTIFS(Inventory!$C$2:$C$381,$B13,Inventory!$J$2:$J$381,"Out of stock") -> 0 | E13: =SUMIF(Inventory!$C$2:$C$381,$B13,Inventory!$H$2:$H$381) -> 0 | G13: Issue Log | H13: Record who took what. Available stock on Inventory drops automatically until you fill the return date.
B14: Cable | C14: =COUNTIF(Inventory!$C$2:$C$381,$B14) -> 7 | D14: =COUNTIFS(Inventory!$C$2:$C$381,$B14,Inventory!$J$2:$J$381,"Low stock")+COUNTIFS(Inventory!$C$2:$C$381,$B14,Inventory!$J$2:$J$381,"Out of stock") -> 1 | E14: =SUMIF(Inventory!$C$2:$C$381,$B14,Inventory!$H$2:$H$381) -> 42 | G14: Locations | H14: Item count and low-stock count for every bin, drawer and box.
B15: Camera | C15: =COUNTIF(Inventory!$C$2:$C$381,$B15) -> 1 | D15: =COUNTIFS(Inventory!$C$2:$C$381,$B15,Inventory!$J$2:$J$381,"Low stock")+COUNTIFS(Inventory!$C$2:$C$381,$B15,Inventory!$J$2:$J$381,"Out of stock") -> 0 | E15: =SUMIF(Inventory!$C$2:$C$381,$B15,Inventory!$H$2:$H$381) -> 2 | G15: Thresholds | H15: The minimum level suggested for each category. Change a single item's Min on the Inventory sheet.
B16: Capacitor | C16: =COUNTIF(Inventory!$C$2:$C$381,$B16) -> 38 | D16: =COUNTIFS(Inventory!$C$2:$C$381,$B16,Inventory!$J$2:$J$381,"Low stock")+COUNTIFS(Inventory!$C$2:$C$381,$B16,Inventory!$J$2:$J$381,"Out of stock") -> 11 | E16: =SUMIF(Inventory!$C$2:$C$381,$B16,Inventory!$H$2:$H$381) -> 938
B17: Chassis | C17: =COUNTIF(Inventory!$C$2:$C$381,$B17) -> 1 | D17: =COUNTIFS(Inventory!$C$2:$C$381,$B17,Inventory!$J$2:$J$381,"Low stock")+COUNTIFS(Inventory!$C$2:$C$381,$B17,Inventory!$J$2:$J$381,"Out of stock") -> 0 | E17: =SUMIF(Inventory!$C$2:$C$381,$B17,Inventory!$H$2:$H$381) -> 0 | G17: Blue figures are yours to edit. Black figures are formulas — changing them breaks the totals.
B18: Connector | C18: =COUNTIF(Inventory!$C$2:$C$381,$B18) -> 11 | D18: =COUNTIFS(Inventory!$C$2:$C$381,$B18,Inventory!$J$2:$J$381,"Low stock")+COUNTIFS(Inventory!$C$2:$C$381,$B18,Inventory!$J$2:$J$381,"Out of stock") -> 2 | E18: =SUMIF(Inventory!$C$2:$C$381,$B18,Inventory!$H$2:$H$381) -> 78
B19: Converter | C19: =COUNTIF(Inventory!$C$2:$C$381,$B19) -> 3 | D19: =COUNTIFS(Inventory!$C$2:$C$381,$B19,Inventory!$J$2:$J$381,"Low stock")+COUNTIFS(Inventory!$C$2:$C$381,$B19,Inventory!$J$2:$J$381,"Out of stock") -> 0 | E19: =SUMIF(Inventory!$C$2:$C$381,$B19,Inventory!$H$2:$H$381) -> 1
B20: Diode | C20: =COUNTIF(Inventory!$C$2:$C$381,$B20) -> 5 | D20: =COUNTIFS(Inventory!$C$2:$C$381,$B20,Inventory!$J$2:$J$381,"Low stock")+COUNTIFS(Inventory!$C$2:$C$381,$B20,Inventory!$J$2:$J$381,"Out of stock") -> 3 | E20: =SUMIF(Inventory!$C$2:$C$381,$B20,Inventory!$H$2:$H$381) -> 8
B21: Display | C21: =COUNTIF(Inventory!$C$2:$C$381,$B21) -> 4 | D21: =COUNTIFS(Inventory!$C$2:$C$381,$B21,Inventory!$J$2:$J$381,"Low stock")+COUNTIFS(Inventory!$C$2:$C$381,$B21,Inventory!$J$2:$J$381,"Out of stock") -> 0 | E21: =SUMIF(Inventory!$C$2:$C$381,$B21,Inventory!$H$2:$H$381) -> 31
B22: Driver | C22: =COUNTIF(Inventory!$C$2:$C$381,$B22) -> 1 | D22: =COUNTIFS(Inventory!$C$2:$C$381,$B22,Inventory!$J$2:$J$381,"Low stock")+COUNTIFS(Inventory!$C$2:$C$381,$B22,Inventory!$J$2:$J$381,"Out of stock") -> 0 | E22: =SUMIF(Inventory!$C$2:$C$381,$B22,Inventory!$H$2:$H$381) -> 5
B23: Fan | C23: =COUNTIF(Inventory!$C$2:$C$381,$B23) -> 1 | D23: =COUNTIFS(Inventory!$C$2:$C$381,$B23,Inventory!$J$2:$J$381,"Low stock")+COUNTIFS(Inventory!$C$2:$C$381,$B23,Inventory!$J$2:$J$381,"Out of stock") -> 0 | E23: =SUMIF(Inventory!$C$2:$C$381,$B23,Inventory!$H$2:$H$381) -> 2
B24: Filter | C24: =COUNTIF(Inventory!$C$2:$C$381,$B24) -> 2 | D24: =COUNTIFS(Inventory!$C$2:$C$381,$B24,Inventory!$J$2:$J$381,"Low stock")+COUNTIFS(Inventory!$C$2:$C$381,$B24,Inventory!$J$2:$J$381,"Out of stock") -> 0 | E24: =SUMIF(Inventory!$C$2:$C$381,$B24,Inventory!$H$2:$H$381) -> 14
B25: Fuse | C25: =COUNTIF(Inventory!$C$2:$C$381,$B25) -> 1 | D25: =COUNTIFS(Inventory!$C$2:$C$381,$B25,Inventory!$J$2:$J$381,"Low stock")+COUNTIFS(Inventory!$C$2:$C$381,$B25,Inventory!$J$2:$J$381,"Out of stock") -> 0 | E25: =SUMIF(Inventory!$C$2:$C$381,$B25,Inventory!$H$2:$H$381) -> 8
B26: Hardware | C26: =COUNTIF(Inventory!$C$2:$C$381,$B26) -> 3 | D26: =COUNTIFS(Inventory!$C$2:$C$381,$B26,Inventory!$J$2:$J$381,"Low stock")+COUNTIFS(Inventory!$C$2:$C$381,$B26,Inventory!$J$2:$J$381,"Out of stock") -> 1 | E26: =SUMIF(Inventory!$C$2:$C$381,$B26,Inventory!$H$2:$H$381) -> 3
B27: Heat Sink | C27: =COUNTIF(Inventory!$C$2:$C$381,$B27) -> 2 | D27: =COUNTIFS(Inventory!$C$2:$C$381,$B27,Inventory!$J$2:$J$381,"Low stock")+COUNTIFS(Inventory!$C$2:$C$381,$B27,Inventory!$J$2:$J$381,"Out of stock") -> 1 | E27: =SUMIF(Inventory!$C$2:$C$381,$B27,Inventory!$H$2:$H$381) -> 7
B28: IC | C28: =COUNTIF(Inventory!$C$2:$C$381,$B28) -> 60 | D28: =COUNTIFS(Inventory!$C$2:$C$381,$B28,Inventory!$J$2:$J$381,"Low stock")+COUNTIFS(Inventory!$C$2:$C$381,$B28,Inventory!$J$2:$J$381,"Out of stock") -> 18 | E28: =SUMIF(Inventory!$C$2:$C$381,$B28,Inventory!$H$2:$H$381) -> 921
B29: IC Base | C29: =COUNTIF(Inventory!$C$2:$C$381,$B29) -> 10 | D29: =COUNTIFS(Inventory!$C$2:$C$381,$B29,Inventory!$J$2:$J$381,"Low stock")+COUNTIFS(Inventory!$C$2:$C$381,$B29,Inventory!$J$2:$J$381,"Out of stock") -> 1 | E29: =SUMIF(Inventory!$C$2:$C$381,$B29,Inventory!$H$2:$H$381) -> 747
... B53: Wire | C53: =COUNTIF(Inventory!$C$2:$C$381,$B53) -> 4 | D53: =COUNTIFS(Inventory!$C$2:$C$381,$B53,Inventory!$J$2:$J$381,"Low stock")+COUNTIFS(Inventory!$C$2:$C$381,$B53,Inventory!$J$2:$J$381,"Out of stock") -> 0 | E53: =SUMIF(Inventory!$C$2:$C$381,$B53,Inventory!$H$2:$H$381) -> 0

Sheet Search
B2: COMPONENT SEARCH
B4: Search for: | C4: resistor | F4: part of a name, a category, or a bin code such as D5
B6: MATCHES | C6: =IF($C$4="","type something above",COUNTIF(Inventory!$M$2:$M$381,1)&" found") -> 46 found
B7: # | C7: Component | D7: Category | E7: LOCATION | F7: Available | G7: Status
B8: 1 | C8: =IFERROR(INDEX(Inventory!$B$2:$B$381,MATCH($B8,Inventory!$N$2:$N$381,0)),"") -> 330 Ω Resistor+ | D8: =IFERROR(INDEX(Inventory!$C$2:$C$381,MATCH($B8,Inventory!$N$2:$N$381,0)),"") -> Resistor | E8: =IFERROR(INDEX(Inventory!$E$2:$E$381,MATCH($B8,Inventory!$N$2:$N$381,0)),"") -> A1 | F8: =IFERROR(INDEX(Inventory!$H$2:$H$381,MATCH($B8,Inventory!$N$2:$N$381,0)),"") -> 10 | G8: =IFERROR(INDEX(Inventory!$J$2:$J$381,MATCH($B8,Inventory!$N$2:$N$381,0)),"") -> In stock
B9: 2 | C9: =IFERROR(INDEX(Inventory!$B$2:$B$381,MATCH($B9,Inventory!$N$2:$N$381,0)),"") -> 70 Ω Resistor+ | D9: =IFERROR(INDEX(Inventory!$C$2:$C$381,MATCH($B9,Inventory!$N$2:$N$381,0)),"") -> Resistor | E9: =IFERROR(INDEX(Inventory!$E$2:$E$381,MATCH($B9,Inventory!$N$2:$N$381,0)),"") -> A1 | F9: =IFERROR(INDEX(Inventory!$H$2:$H$381,MATCH($B9,Inventory!$N$2:$N$381,0)),"") -> 5 | G9: =IFERROR(INDEX(Inventory!$J$2:$J$381,MATCH($B9,Inventory!$N$2:$N$381,0)),"") -> Low stock
B10: 3 | C10: =IFERROR(INDEX(Inventory!$B$2:$B$381,MATCH($B10,Inventory!$N$2:$N$381,0)),"") -> 68 Ω Resistor+ | D10: =IFERROR(INDEX(Inventory!$C$2:$C$381,MATCH($B10,Inventory!$N$2:$N$381,0)),"") -> Resistor | E10: =IFERROR(INDEX(Inventory!$E$2:$E$381,MATCH($B10,Inventory!$N$2:$N$381,0)),"") -> A1 | F10: =IFERROR(INDEX(Inventory!$H$2:$H$381,MATCH($B10,Inventory!$N$2:$N$381,0)),"") -> 150 | G10: =IFERROR(INDEX(Inventory!$J$2:$J$381,MATCH($B10,Inventory!$N$2:$N$381,0)),"") -> In stock
B11: 4 | C11: =IFERROR(INDEX(Inventory!$B$2:$B$381,MATCH($B11,Inventory!$N$2:$N$381,0)),"") -> 100 Ω Resistor+ | D11: =IFERROR(INDEX(Inventory!$C$2:$C$381,MATCH($B11,Inventory!$N$2:$N$381,0)),"") -> Resistor | E11: =IFERROR(INDEX(Inventory!$E$2:$E$381,MATCH($B11,Inventory!$N$2:$N$381,0)),"") -> A1 | F11: =IFERROR(INDEX(Inventory!$H$2:$H$381,MATCH($B11,Inventory!$N$2:$N$381,0)),"") -> 25 | G11: =IFERROR(INDEX(Inventory!$J$2:$J$381,MATCH($B11,Inventory!$N$2:$N$381,0)),"") -> In stock
B12: 5 | C12: =IFERROR(INDEX(Inventory!$B$2:$B$381,MATCH($B12,Inventory!$N$2:$N$381,0)),"") -> 5.2 Ω Resistor+ | D12: =IFERROR(INDEX(Inventory!$C$2:$C$381,MATCH($B12,Inventory!$N$2:$N$381,0)),"") -> Resistor | E12: =IFERROR(INDEX(Inventory!$E$2:$E$381,MATCH($B12,Inventory!$N$2:$N$381,0)),"") -> A1 | F12: =IFERROR(INDEX(Inventory!$H$2:$H$381,MATCH($B12,Inventory!$N$2:$N$381,0)),"") -> 20 | G12: =IFERROR(INDEX(Inventory!$J$2:$J$381,MATCH($B12,Inventory!$N$2:$N$381,0)),"") -> In stock
B13: 6 | C13: =IFERROR(INDEX(Inventory!$B$2:$B$381,MATCH($B13,Inventory!$N$2:$N$381,0)),"") -> 150K Ω Resistor+ | D13: =IFERROR(INDEX(Inventory!$C$2:$C$381,MATCH($B13,Inventory!$N$2:$N$381,0)),"") -> Resistor | E13: =IFERROR(INDEX(Inventory!$E$2:$E$381,MATCH($B13,Inventory!$N$2:$N$381,0)),"") -> A1 | F13: =IFERROR(INDEX(Inventory!$H$2:$H$381,MATCH($B13,Inventory!$N$2:$N$381,0)),"") -> 10 | G13: =IFERROR(INDEX(Inventory!$J$2:$J$381,MATCH($B13,Inventory!$N$2:$N$381,0)),"") -> In stock
B14: 7 | C14: =IFERROR(INDEX(Inventory!$B$2:$B$381,MATCH($B14,Inventory!$N$2:$N$381,0)),"") -> 15K Ω Resistor+ | D14: =IFERROR(INDEX(Inventory!$C$2:$C$381,MATCH($B14,Inventory!$N$2:$N$381,0)),"") -> Resistor | E14: =IFERROR(INDEX(Inventory!$E$2:$E$381,MATCH($B14,Inventory!$N$2:$N$381,0)),"") -> A1 | F14: =IFERROR(INDEX(Inventory!$H$2:$H$381,MATCH($B14,Inventory!$N$2:$N$381,0)),"") -> 15 | G14: =IFERROR(INDEX(Inventory!$J$2:$J$381,MATCH($B14,Inventory!$N$2:$N$381,0)),"") -> In stock
B15: 8 | C15: =IFERROR(INDEX(Inventory!$B$2:$B$381,MATCH($B15,Inventory!$N$2:$N$381,0)),"") -> 220 Ω Resistor+ | D15: =IFERROR(INDEX(Inventory!$C$2:$C$381,MATCH($B15,Inventory!$N$2:$N$381,0)),"") -> Resistor | E15: =IFERROR(INDEX(Inventory!$E$2:$E$381,MATCH($B15,Inventory!$N$2:$N$381,0)),"") -> A2 | F15: =IFERROR(INDEX(Inventory!$H$2:$H$381,MATCH($B15,Inventory!$N$2:$N$381,0)),"") -> 50 | G15: =IFERROR(INDEX(Inventory!$J$2:$J$381,MATCH($B15,Inventory!$N$2:$N$381,0)),"") -> In stock
B16: 9 | C16: =IFERROR(INDEX(Inventory!$B$2:$B$381,MATCH($B16,Inventory!$N$2:$N$381,0)),"") -> 10K Ω Resistor+ | D16: =IFERROR(INDEX(Inventory!$C$2:$C$381,MATCH($B16,Inventory!$N$2:$N$381,0)),"") -> Resistor | E16: =IFERROR(INDEX(Inventory!$E$2:$E$381,MATCH($B16,Inventory!$N$2:$N$381,0)),"") -> A2 | F16: =IFERROR(INDEX(Inventory!$H$2:$H$381,MATCH($B16,Inventory!$N$2:$N$381,0)),"") -> 50 | G16: =IFERROR(INDEX(Inventory!$J$2:$J$381,MATCH($B16,Inventory!$N$2:$N$381,0)),"") -> In stock
B17: 10 | C17: =IFERROR(INDEX(Inventory!$B$2:$B$381,MATCH($B17,Inventory!$N$2:$N$381,0)),"") -> 330K Ω Resistor+ | D17: =IFERROR(INDEX(Inventory!$C$2:$C$381,MATCH($B17,Inventory!$N$2:$N$381,0)),"") -> Resistor | E17: =IFERROR(INDEX(Inventory!$E$2:$E$381,MATCH($B17,Inventory!$N$2:$N$381,0)),"") -> A2 | F17: =IFERROR(INDEX(Inventory!$H$2:$H$381,MATCH($B17,Inventory!$N$2:$N$381,0)),"") -> 25 | G17: =IFERROR(INDEX(Inventory!$J$2:$J$381,MATCH($B17,Inventory!$N$2:$N$381,0)),"") -> In stock
B18: 11 | C18: =IFERROR(INDEX(Inventory!$B$2:$B$381,MATCH($B18,Inventory!$N$2:$N$381,0)),"") -> 470 Ω Resistor+ | D18: =IFERROR(INDEX(Inventory!$C$2:$C$381,MATCH($B18,Inventory!$N$2:$N$381,0)),"") -> Resistor | E18: =IFERROR(INDEX(Inventory!$E$2:$E$381,MATCH($B18,Inventory!$N$2:$N$381,0)),"") -> A2 | F18: =IFERROR(INDEX(Inventory!$H$2:$H$381,MATCH($B18,Inventory!$N$2:$N$381,0)),"") -> 10 | G18: =IFERROR(INDEX(Inventory!$J$2:$J$381,MATCH($B18,Inventory!$N$2:$N$381,0)),"") -> In stock
B19: 12 | C19: =IFERROR(INDEX(Inventory!$B$2:$B$381,MATCH($B19,Inventory!$N$2:$N$381,0)),"") -> 4.7K Ω Resistor+ | D19: =IFERROR(INDEX(Inventory!$C$2:$C$381,MATCH($B19,Inventory!$N$2:$N$381,0)),"") -> Resistor | E19: =IFERROR(INDEX(Inventory!$E$2:$E$381,MATCH($B19,Inventory!$N$2:$N$381,0)),"") -> A2 | F19: =IFERROR(INDEX(Inventory!$H$2:$H$381,MATCH($B19,Inventory!$N$2:$N$381,0)),"") -> 30 | G19: =IFERROR(INDEX(Inventory!$J$2:$J$381,MATCH($B19,Inventory!$N$2:$N$381,0)),"") -> In stock
... B47: 40 | C47: =IFERROR(INDEX(Inventory!$B$2:$B$381,MATCH($B47,Inventory!$N$2:$N$381,0)),"") -> 55K Ω Resistor+ | D47: =IFERROR(INDEX(Inventory!$C$2:$C$381,MATCH($B47,Inventory!$N$2:$N$381,0)),"") -> Resistor | E47: =IFERROR(INDEX(Inventory!$E$2:$E$381,MATCH($B47,Inventory!$N$2:$N$381,0)),"") -> MIXED RESISTOR BOX | F47: =IFERROR(INDEX(Inventory!$H$2:$H$381,MATCH($B47,Inventory!$N$2:$N$381,0)),"") -> 5 | G47: =IFERROR(INDEX(Inventory!$J$2:$J$381,MATCH($B47,Inventory!$N$2:$N$381,0)),"") -> Low stock

Sheet Low Stock
B2: RESTOCKING LIST
B3: Everything out of stock, below its minimum, or never counted. Rebuilds itself from the Inventory sheet.
B5: # | C5: Component | D5: Category | E5: Location | F5: Available | G5: Min | H5: Short by | I5: Status
B6: 1 | C6: =IFERROR(INDEX(Inventory!$B$2:$B$381,MATCH($B6,Inventory!$P$2:$P$381,0)),"") -> 70 Ω Resistor+ | D6: =IFERROR(INDEX(Inventory!$C$2:$C$381,MATCH($B6,Inventory!$P$2:$P$381,0)),"") -> Resistor | E6: =IFERROR(INDEX(Inventory!$E$2:$E$381,MATCH($B6,Inventory!$P$2:$P$381,0)),"") -> A1 | F6: =IFERROR(INDEX(Inventory!$H$2:$H$381,MATCH($B6,Inventory!$P$2:$P$381,0)),"") -> 5 | G6: =IFERROR(INDEX(Inventory!$I$2:$I$381,MATCH($B6,Inventory!$P$2:$P$381,0)),"") -> 10 | H6: =IF($C6="","",IF($F6="","count it",MAX(0,$G6-$F6))) -> 5 | I6: =IFERROR(INDEX(Inventory!$J$2:$J$381,MATCH($B6,Inventory!$P$2:$P$381,0)),"") -> Low stock
B7: 2 | C7: =IFERROR(INDEX(Inventory!$B$2:$B$381,MATCH($B7,Inventory!$P$2:$P$381,0)),"") -> 4.7K Ω Preset Potentiometer | D7: =IFERROR(INDEX(Inventory!$C$2:$C$381,MATCH($B7,Inventory!$P$2:$P$381,0)),"") -> Potentiometer | E7: =IFERROR(INDEX(Inventory!$E$2:$E$381,MATCH($B7,Inventory!$P$2:$P$381,0)),"") -> A3 | F7: =IFERROR(INDEX(Inventory!$H$2:$H$381,MATCH($B7,Inventory!$P$2:$P$381,0)),"") -> 3 | G7: =IFERROR(INDEX(Inventory!$I$2:$I$381,MATCH($B7,Inventory!$P$2:$P$381,0)),"") -> 4 | H7: =IF($C7="","",IF($F7="","count it",MAX(0,$G7-$F7))) -> 1 | I7: =IFERROR(INDEX(Inventory!$J$2:$J$381,MATCH($B7,Inventory!$P$2:$P$381,0)),"") -> Low stock
B8: 3 | C8: =IFERROR(INDEX(Inventory!$B$2:$B$381,MATCH($B8,Inventory!$P$2:$P$381,0)),"") -> 10K Ω Preset Potentiometer | D8: =IFERROR(INDEX(Inventory!$C$2:$C$381,MATCH($B8,Inventory!$P$2:$P$381,0)),"") -> Potentiometer | E8: =IFERROR(INDEX(Inventory!$E$2:$E$381,MATCH($B8,Inventory!$P$2:$P$381,0)),"") -> A3 | F8: =IFERROR(INDEX(Inventory!$H$2:$H$381,MATCH($B8,Inventory!$P$2:$P$381,0)),"") -> 3 | G8: =IFERROR(INDEX(Inventory!$I$2:$I$381,MATCH($B8,Inventory!$P$2:$P$381,0)),"") -> 4 | H8: =IF($C8="","",IF($F8="","count it",MAX(0,$G8-$F8))) -> 1 | I8: =IFERROR(INDEX(Inventory!$J$2:$J$381,MATCH($B8,Inventory!$P$2:$P$381,0)),"") -> Low stock
B9: 4 | C9: =IFERROR(INDEX(Inventory!$B$2:$B$381,MATCH($B9,Inventory!$P$2:$P$381,0)),"") -> Microphone and Microphone Module | D9: =IFERROR(INDEX(Inventory!$C$2:$C$381,MATCH($B9,Inventory!$P$2:$P$381,0)),"") -> Microphone | E9: =IFERROR(INDEX(Inventory!$E$2:$E$381,MATCH($B9,Inventory!$P$2:$P$381,0)),"") -> A4 | F9: =IFERROR(INDEX(Inventory!$H$2:$H$381,MATCH($B9,Inventory!$P$2:$P$381,0)),"") | G9: =IFERROR(INDEX(Inventory!$I$2:$I$381,MATCH($B9,Inventory!$P$2:$P$381,0)),"") -> 2 | H9: =IF($C9="","",IF($F9="","count it",MAX(0,$G9-$F9))) -> count it | I9: =IFERROR(INDEX(Inventory!$J$2:$J$381,MATCH($B9,Inventory!$P$2:$P$381,0)),"") -> Not counted
B10: 5 | C10: =IFERROR(INDEX(Inventory!$B$2:$B$381,MATCH($B10,Inventory!$P$2:$P$381,0)),"") -> Speacker Speacker Module | D10: =IFERROR(INDEX(Inventory!$C$2:$C$381,MATCH($B10,Inventory!$P$2:$P$381,0)),"") -> Speaker | E10: =IFERROR(INDEX(Inventory!$E$2:$E$381,MATCH($B10,Inventory!$P$2:$P$381,0)),"") -> A4 | F10: =IFERROR(INDEX(Inventory!$H$2:$H$381,MATCH($B10,Inventory!$P$2:$P$381,0)),"") | G10: =IFERROR(INDEX(Inventory!$I$2:$I$381,MATCH($B10,Inventory!$P$2:$P$381,0)),"") -> 1 | H10: =IF($C10="","",IF($F10="","count it",MAX(0,$G10-$F10))) -> count it | I10: =IFERROR(INDEX(Inventory!$J$2:$J$381,MATCH($B10,Inventory!$P$2:$P$381,0)),"") -> Not counted
B11: 6 | C11: =IFERROR(INDEX(Inventory!$B$2:$B$381,MATCH($B11,Inventory!$P$2:$P$381,0)),"") -> 2.7 Non polarised Capacitor | D11: =IFERROR(INDEX(Inventory!$C$2:$C$381,MATCH($B11,Inventory!$P$2:$P$381,0)),"") -> Capacitor | E11: =IFERROR(INDEX(Inventory!$E$2:$E$381,MATCH($B11,Inventory!$P$2:$P$381,0)),"") -> A5 | F11: =IFERROR(INDEX(Inventory!$H$2:$H$381,MATCH($B11,Inventory!$P$2:$P$381,0)),"") -> 6 | G11: =IFERROR(INDEX(Inventory!$I$2:$I$381,MATCH($B11,Inventory!$P$2:$P$381,0)),"") -> 10 | H11: =IF($C11="","",IF($F11="","count it",MAX(0,$G11-$F11))) -> 4 | I11: =IFERROR(INDEX(Inventory!$J$2:$J$381,MATCH($B11,Inventory!$P$2:$P$381,0)),"") -> Low stock
B12: 7 | C12: =IFERROR(INDEX(Inventory!$B$2:$B$381,MATCH($B12,Inventory!$P$2:$P$381,0)),"") -> 47 Non polarised Capacitor | D12: =IFERROR(INDEX(Inventory!$C$2:$C$381,MATCH($B12,Inventory!$P$2:$P$381,0)),"") -> Capacitor | E12: =IFERROR(INDEX(Inventory!$E$2:$E$381,MATCH($B12,Inventory!$P$2:$P$381,0)),"") -> A5 | F12: =IFERROR(INDEX(Inventory!$H$2:$H$381,MATCH($B12,Inventory!$P$2:$P$381,0)),"") -> 6 | G12: =IFERROR(INDEX(Inventory!$I$2:$I$381,MATCH($B12,Inventory!$P$2:$P$381,0)),"") -> 10 | H12: =IF($C12="","",IF($F12="","count it",MAX(0,$G12-$F12))) -> 4 | I12: =IFERROR(INDEX(Inventory!$J$2:$J$381,MATCH($B12,Inventory!$P$2:$P$381,0)),"") -> Low stock
B13: 8 | C13: =IFERROR(INDEX(Inventory!$B$2:$B$381,MATCH($B13,Inventory!$P$2:$P$381,0)),"") -> 56 Non Polarised Capacitor | D13: =IFERROR(INDEX(Inventory!$C$2:$C$381,MATCH($B13,Inventory!$P$2:$P$381,0)),"") -> Capacitor | E13: =IFERROR(INDEX(Inventory!$E$2:$E$381,MATCH($B13,Inventory!$P$2:$P$381,0)),"") -> A5 | F13: =IFERROR(INDEX(Inventory!$H$2:$H$381,MATCH($B13,Inventory!$P$2:$P$381,0)),"") -> 8 | G13: =IFERROR(INDEX(Inventory!$I$2:$I$381,MATCH($B13,Inventory!$P$2:$P$381,0)),"") -> 10 | H13: =IF($C13="","",IF($F13="","count it",MAX(0,$G13-$F13))) -> 2 | I13: =IFERROR(INDEX(Inventory!$J$2:$J$381,MATCH($B13,Inventory!$P$2:$P$381,0)),"") -> Low stock
B14: 9 | C14: =IFERROR(INDEX(Inventory!$B$2:$B$381,MATCH($B14,Inventory!$P$2:$P$381,0)),"") -> 2.2uf 63v Capacitor | D14: =IFERROR(INDEX(Inventory!$C$2:$C$381,MATCH($B14,Inventory!$P$2:$P$381,0)),"") -> Capacitor | E14: =IFERROR(INDEX(Inventory!$E$2:$E$381,MATCH($B14,Inventory!$P$2:$P$381,0)),"") -> A6 | F14: =IFERROR(INDEX(Inventory!$H$2:$H$381,MATCH($B14,Inventory!$P$2:$P$381,0)),"") -> 7 | G14: =IFERROR(INDEX(Inventory!$I$2:$I$381,MATCH($B14,Inventory!$P$2:$P$381,0)),"") -> 10 | H14: =IF($C14="","",IF($F14="","count it",MAX(0,$G14-$F14))) -> 3 | I14: =IFERROR(INDEX(Inventory!$J$2:$J$381,MATCH($B14,Inventory!$P$2:$P$381,0)),"") -> Low stock
B15: 10 | C15: =IFERROR(INDEX(Inventory!$B$2:$B$381,MATCH($B15,Inventory!$P$2:$P$381,0)),"") -> 10uf 50v Capacitor | D15: =IFERROR(INDEX(Inventory!$C$2:$C$381,MATCH($B15,Inventory!$P$2:$P$381,0)),"") -> Capacitor | E15: =IFERROR(INDEX(Inventory!$E$2:$E$381,MATCH($B15,Inventory!$P$2:$P$381,0)),"") -> A6 | F15: =IFERROR(INDEX(Inventory!$H$2:$H$381,MATCH($B15,Inventory!$P$2:$P$381,0)),"") -> 7 | G15: =IFERROR(INDEX(Inventory!$I$2:$I$381,MATCH($B15,Inventory!$P$2:$P$381,0)),"") -> 10 | H15: =IF($C15="","",IF($F15="","count it",MAX(0,$G15-$F15))) -> 3 | I15: =IFERROR(INDEX(Inventory!$J$2:$J$381,MATCH($B15,Inventory!$P$2:$P$381,0)),"") -> Low stock
B16: 11 | C16: =IFERROR(INDEX(Inventory!$B$2:$B$381,MATCH($B16,Inventory!$P$2:$P$381,0)),"") -> 16MHz Oscillator | D16: =IFERROR(INDEX(Inventory!$C$2:$C$381,MATCH($B16,Inventory!$P$2:$P$381,0)),"") -> Oscillator | E16: =IFERROR(INDEX(Inventory!$E$2:$E$381,MATCH($B16,Inventory!$P$2:$P$381,0)),"") -> B6 | F16: =IFERROR(INDEX(Inventory!$H$2:$H$381,MATCH($B16,Inventory!$P$2:$P$381,0)),"") -> 2 | G16: =IFERROR(INDEX(Inventory!$I$2:$I$381,MATCH($B16,Inventory!$P$2:$P$381,0)),"") -> 5 | H16: =IF($C16="","",IF($F16="","count it",MAX(0,$G16-$F16))) -> 3 | I16: =IFERROR(INDEX(Inventory!$J$2:$J$381,MATCH($B16,Inventory!$P$2:$P$381,0)),"") -> Low stock
B17: 12 | C17: =IFERROR(INDEX(Inventory!$B$2:$B$381,MATCH($B17,Inventory!$P$2:$P$381,0)),"") -> Photo Diode Reciever | D17: =IFERROR(INDEX(Inventory!$C$2:$C$381,MATCH($B17,Inventory!$P$2:$P$381,0)),"") -> LED | E17: =IFERROR(INDEX(Inventory!$E$2:$E$381,MATCH($B17,Inventory!$P$2:$P$381,0)),"") -> B8 | F17: =IFERROR(INDEX(Inventory!$H$2:$H$381,MATCH($B17,Inventory!$P$2:$P$381,0)),"") -> 2 | G17: =IFERROR(INDEX(Inventory!$I$2:$I$381,MATCH($B17,Inventory!$P$2:$P$381,0)),"") -> 5 | H17: =IF($C17="","",IF($F17="","count it",MAX(0,$G17-$F17))) -> 3 | I17: =IFERROR(INDEX(Inventory!$J$2:$J$381,MATCH($B17,Inventory!$P$2:$P$381,0)),"") -> Low stock
... B205: 200 | C205: =IFERROR(INDEX(Inventory!$B$2:$B$381,MATCH($B205,Inventory!$P$2:$P$381,0)),"") | D205: =IFERROR(INDEX(Inventory!$C$2:$C$381,MATCH($B205,Inventory!$P$2:$P$381,0)),"") | E205: =IFERROR(INDEX(Inventory!$E$2:$E$381,MATCH($B205,Inventory!$P$2:$P$381,0)),"") | F205: =IFERROR(INDEX(Inventory!$H$2:$H$381,MATCH($B205,Inventory!$P$2:$P$381,0)),"") | G205: =IFERROR(INDEX(Inventory!$I$2:$I$381,MATCH($B205,Inventory!$P$2:$P$381,0)),"") | H205: =IF($C205="","",IF($F205="","count it",MAX(0,$G205-$F205))) | I205: =IFERROR(INDEX(Inventory!$J$2:$J$381,MATCH($B205,Inventory!$P$2:$P$381,0)),"")

Sheet Issue Log
A1: Date issued | B1: Component ID | C1: Component | D1: Location | E1: Issued to | F1: Purpose | G1: Qty issued | H1: Date returned | I1: Qty returned | J1: Status
A2: 2026-09-08 | B2: EC013 | C2: =IF($B2="","",IFERROR(INDEX(Inventory!$B$2:$B$381,MATCH($B2,Inventory!$A$2:$A$381,0)),"unknown ID")) -> 1K Ω Resistor+ | D2: =IF($B2="","",IFERROR(INDEX(Inventory!$E$2:$E$381,MATCH($B2,Inventory!$A$2:$A$381,0)),"")) -> A2 | E2: EXAMPLE — Ananya S. | F2: Mini project (delete this row) | G2: 10 | H2: 2026-09-09 | I2: 10 | J2: =IF($B2="","",IF($H2="","Out","Returned")) -> Returned
C3: =IF($B3="","",IFERROR(INDEX(Inventory!$B$2:$B$381,MATCH($B3,Inventory!$A$2:$A$381,0)),"unknown ID")) | D3: =IF($B3="","",IFERROR(INDEX(Inventory!$E$2:$E$381,MATCH($B3,Inventory!$A$2:$A$381,0)),"")) | J3: =IF($B3="","",IF($H3="","Out","Returned"))
C4: =IF($B4="","",IFERROR(INDEX(Inventory!$B$2:$B$381,MATCH($B4,Inventory!$A$2:$A$381,0)),"unknown ID")) | D4: =IF($B4="","",IFERROR(INDEX(Inventory!$E$2:$E$381,MATCH($B4,Inventory!$A$2:$A$381,0)),"")) | J4: =IF($B4="","",IF($H4="","Out","Returned"))
C5: =IF($B5="","",IFERROR(INDEX(Inventory!$B$2:$B$381,MATCH($B5,Inventory!$A$2:$A$381,0)),"unknown ID")) | D5: =IF($B5="","",IFERROR(INDEX(Inventory!$E$2:$E$381,MATCH($B5,Inventory!$A$2:$A$381,0)),"")) | J5: =IF($B5="","",IF($H5="","Out","Returned"))
C6: =IF($B6="","",IFERROR(INDEX(Inventory!$B$2:$B$381,MATCH($B6,Inventory!$A$2:$A$381,0)),"unknown ID")) | D6: =IF($B6="","",IFERROR(INDEX(Inventory!$E$2:$E$381,MATCH($B6,Inventory!$A$2:$A$381,0)),"")) | J6: =IF($B6="","",IF($H6="","Out","Returned"))
C7: =IF($B7="","",IFERROR(INDEX(Inventory!$B$2:$B$381,MATCH($B7,Inventory!$A$2:$A$381,0)),"unknown ID")) | D7: =IF($B7="","",IFERROR(INDEX(Inventory!$E$2:$E$381,MATCH($B7,Inventory!$A$2:$A$381,0)),"")) | J7: =IF($B7="","",IF($H7="","Out","Returned"))
C8: =IF($B8="","",IFERROR(INDEX(Inventory!$B$2:$B$381,MATCH($B8,Inventory!$A$2:$A$381,0)),"unknown ID")) | D8: =IF($B8="","",IFERROR(INDEX(Inventory!$E$2:$E$381,MATCH($B8,Inventory!$A$2:$A$381,0)),"")) | J8: =IF($B8="","",IF($H8="","Out","Returned"))
C9: =IF($B9="","",IFERROR(INDEX(Inventory!$B$2:$B$381,MATCH($B9,Inventory!$A$2:$A$381,0)),"unknown ID")) | D9: =IF($B9="","",IFERROR(INDEX(Inventory!$E$2:$E$381,MATCH($B9,Inventory!$A$2:$A$381,0)),"")) | J9: =IF($B9="","",IF($H9="","Out","Returned"))
C10: =IF($B10="","",IFERROR(INDEX(Inventory!$B$2:$B$381,MATCH($B10,Inventory!$A$2:$A$381,0)),"unknown ID")) | D10: =IF($B10="","",IFERROR(INDEX(Inventory!$E$2:$E$381,MATCH($B10,Inventory!$A$2:$A$381,0)),"")) | J10: =IF($B10="","",IF($H10="","Out","Returned"))
C11: =IF($B11="","",IFERROR(INDEX(Inventory!$B$2:$B$381,MATCH($B11,Inventory!$A$2:$A$381,0)),"unknown ID")) | D11: =IF($B11="","",IFERROR(INDEX(Inventory!$E$2:$E$381,MATCH($B11,Inventory!$A$2:$A$381,0)),"")) | J11: =IF($B11="","",IF($H11="","Out","Returned"))
C12: =IF($B12="","",IFERROR(INDEX(Inventory!$B$2:$B$381,MATCH($B12,Inventory!$A$2:$A$381,0)),"unknown ID")) | D12: =IF($B12="","",IFERROR(INDEX(Inventory!$E$2:$E$381,MATCH($B12,Inventory!$A$2:$A$381,0)),"")) | J12: =IF($B12="","",IF($H12="","Out","Returned"))
C13: =IF($B13="","",IFERROR(INDEX(Inventory!$B$2:$B$381,MATCH($B13,Inventory!$A$2:$A$381,0)),"unknown ID")) | D13: =IF($B13="","",IFERROR(INDEX(Inventory!$E$2:$E$381,MATCH($B13,Inventory!$A$2:$A$381,0)),"")) | J13: =IF($B13="","",IF($H13="","Out","Returned"))
C14: =IF($B14="","",IFERROR(INDEX(Inventory!$B$2:$B$381,MATCH($B14,Inventory!$A$2:$A$381,0)),"unknown ID")) | D14: =IF($B14="","",IFERROR(INDEX(Inventory!$E$2:$E$381,MATCH($B14,Inventory!$A$2:$A$381,0)),"")) | J14: =IF($B14="","",IF($H14="","Out","Returned"))
... C501: =IF($B501="","",IFERROR(INDEX(Inventory!$B$2:$B$381,MATCH($B501,Inventory!$A$2:$A$381,0)),"unknown ID")) | D501: =IF($B501="","",IFERROR(INDEX(Inventory!$E$2:$E$381,MATCH($B501,Inventory!$A$2:$A$381,0)),"")) | J501: =IF($B501="","",IF($H501="","Out","Returned"))

Sheet Locations
B2: RACK & BIN MAP
B3: Every storage position in the lab and what it holds.
B5: Location | C5: Items | D5: Low / Out | E5: Available units | F5: Main category
B6: A1 | C6: =COUNTIF(Inventory!$E$2:$E$381,$B6) -> 7 | D6: =COUNTIFS(Inventory!$E$2:$E$381,$B6,Inventory!$J$2:$J$381,"Low stock")+COUNTIFS(Inventory!$E$2:$E$381,$B6,Inventory!$J$2:$J$381,"Out of stock") -> 1 | E6: =SUMIF(Inventory!$E$2:$E$381,$B6,Inventory!$H$2:$H$381) -> 235 | F6: Resistor
B7: A2 | C7: =COUNTIF(Inventory!$E$2:$E$381,$B7) -> 6 | D7: =COUNTIFS(Inventory!$E$2:$E$381,$B7,Inventory!$J$2:$J$381,"Low stock")+COUNTIFS(Inventory!$E$2:$E$381,$B7,Inventory!$J$2:$J$381,"Out of stock") -> 0 | E7: =SUMIF(Inventory!$E$2:$E$381,$B7,Inventory!$H$2:$H$381) -> 215 | F7: Resistor
B8: A3 | C8: =COUNTIF(Inventory!$E$2:$E$381,$B8) -> 7 | D8: =COUNTIFS(Inventory!$E$2:$E$381,$B8,Inventory!$J$2:$J$381,"Low stock")+COUNTIFS(Inventory!$E$2:$E$381,$B8,Inventory!$J$2:$J$381,"Out of stock") -> 2 | E8: =SUMIF(Inventory!$E$2:$E$381,$B8,Inventory!$H$2:$H$381) -> 126 | F8: Potentiometer
B9: A4 | C9: =COUNTIF(Inventory!$E$2:$E$381,$B9) -> 5 | D9: =COUNTIFS(Inventory!$E$2:$E$381,$B9,Inventory!$J$2:$J$381,"Low stock")+COUNTIFS(Inventory!$E$2:$E$381,$B9,Inventory!$J$2:$J$381,"Out of stock") -> 0 | E9: =SUMIF(Inventory!$E$2:$E$381,$B9,Inventory!$H$2:$H$381) -> 46 | F9: Microphone
B10: A5 | C10: =COUNTIF(Inventory!$E$2:$E$381,$B10) -> 13 | D10: =COUNTIFS(Inventory!$E$2:$E$381,$B10,Inventory!$J$2:$J$381,"Low stock")+COUNTIFS(Inventory!$E$2:$E$381,$B10,Inventory!$J$2:$J$381,"Out of stock") -> 3 | E10: =SUMIF(Inventory!$E$2:$E$381,$B10,Inventory!$H$2:$H$381) -> 477 | F10: Capacitor
B11: A6 | C11: =COUNTIF(Inventory!$E$2:$E$381,$B11) -> 11 | D11: =COUNTIFS(Inventory!$E$2:$E$381,$B11,Inventory!$J$2:$J$381,"Low stock")+COUNTIFS(Inventory!$E$2:$E$381,$B11,Inventory!$J$2:$J$381,"Out of stock") -> 2 | E11: =SUMIF(Inventory!$E$2:$E$381,$B11,Inventory!$H$2:$H$381) -> 250 | F11: Capacitor
B12: A7 | C12: =COUNTIF(Inventory!$E$2:$E$381,$B12) -> 5 | D12: =COUNTIFS(Inventory!$E$2:$E$381,$B12,Inventory!$J$2:$J$381,"Low stock")+COUNTIFS(Inventory!$E$2:$E$381,$B12,Inventory!$J$2:$J$381,"Out of stock") -> 0 | E12: =SUMIF(Inventory!$E$2:$E$381,$B12,Inventory!$H$2:$H$381) -> 245 | F12: Resistor
B13: A8 | C13: =COUNTIF(Inventory!$E$2:$E$381,$B13) -> 19 | D13: =COUNTIFS(Inventory!$E$2:$E$381,$B13,Inventory!$J$2:$J$381,"Low stock")+COUNTIFS(Inventory!$E$2:$E$381,$B13,Inventory!$J$2:$J$381,"Out of stock") -> 10 | E13: =SUMIF(Inventory!$E$2:$E$381,$B13,Inventory!$H$2:$H$381) -> 35 | F13: Sensor
B14: A9 | C14: =COUNTIF(Inventory!$E$2:$E$381,$B14) -> 14 | D14: =COUNTIFS(Inventory!$E$2:$E$381,$B14,Inventory!$J$2:$J$381,"Low stock")+COUNTIFS(Inventory!$E$2:$E$381,$B14,Inventory!$J$2:$J$381,"Out of stock") -> 13 | E14: =SUMIF(Inventory!$E$2:$E$381,$B14,Inventory!$H$2:$H$381) -> 15 | F14: Module
B15: ADAPTER BOX | C15: =COUNTIF(Inventory!$E$2:$E$381,$B15) -> 5 | D15: =COUNTIFS(Inventory!$E$2:$E$381,$B15,Inventory!$J$2:$J$381,"Low stock")+COUNTIFS(Inventory!$E$2:$E$381,$B15,Inventory!$J$2:$J$381,"Out of stock") -> 2 | E15: =SUMIF(Inventory!$E$2:$E$381,$B15,Inventory!$H$2:$H$381) -> 21 | F15: Power
B16: ARDUINO CABLE BOX | C16: =COUNTIF(Inventory!$E$2:$E$381,$B16) -> 1 | D16: =COUNTIFS(Inventory!$E$2:$E$381,$B16,Inventory!$J$2:$J$381,"Low stock")+COUNTIFS(Inventory!$E$2:$E$381,$B16,Inventory!$J$2:$J$381,"Out of stock") -> 0 | E16: =SUMIF(Inventory!$E$2:$E$381,$B16,Inventory!$H$2:$H$381) -> 1 | F16: Converter
B17: B1 | C17: =COUNTIF(Inventory!$E$2:$E$381,$B17) -> 5 | D17: =COUNTIFS(Inventory!$E$2:$E$381,$B17,Inventory!$J$2:$J$381,"Low stock")+COUNTIFS(Inventory!$E$2:$E$381,$B17,Inventory!$J$2:$J$381,"Out of stock") -> 0 | E17: =SUMIF(Inventory!$E$2:$E$381,$B17,Inventory!$H$2:$H$381) -> 111 | F17: Battery
... B63: UNASSIGNED | C63: =COUNTIF(Inventory!$E$2:$E$381,$B63) -> 49 | D63: =COUNTIFS(Inventory!$E$2:$E$381,$B63,Inventory!$J$2:$J$381,"Low stock")+COUNTIFS(Inventory!$E$2:$E$381,$B63,Inventory!$J$2:$J$381,"Out of stock") -> 5 | E63: =SUMIF(Inventory!$E$2:$E$381,$B63,Inventory!$H$2:$H$381) -> 210 | F63: Soldering

Sheet Thresholds
B2: LOW-STOCK MINIMUMS BY CATEGORY
B3: Reference values used when the register was imported. To change how one component behaves, edit its Min on the Inventory sheet — that is what the Status formula reads.
B5: Category | C5: Suggested minimum | D5: Items in this category
B6: Antenna | C6: 1 | D6: =COUNTIF(Inventory!$C$2:$C$381,$B6) -> 2
B7: Battery | C7: 2 | D7: =COUNTIF(Inventory!$C$2:$C$381,$B7) -> 10
B8: Buzzer | C8: 1 | D8: =COUNTIF(Inventory!$C$2:$C$381,$B8) -> 1
B9: Cable | C9: 2 | D9: =COUNTIF(Inventory!$C$2:$C$381,$B9) -> 7
B10: Camera | C10: 1 | D10: =COUNTIF(Inventory!$C$2:$C$381,$B10) -> 1
B11: Capacitor | C11: 10 | D11: =COUNTIF(Inventory!$C$2:$C$381,$B11) -> 38
B12: Chassis | C12: 1 | D12: =COUNTIF(Inventory!$C$2:$C$381,$B12) -> 1
B13: Connector | C13: 4 | D13: =COUNTIF(Inventory!$C$2:$C$381,$B13) -> 11
B14: Converter | C14: 1 | D14: =COUNTIF(Inventory!$C$2:$C$381,$B14) -> 3
B15: Diode | C15: 5 | D15: =COUNTIF(Inventory!$C$2:$C$381,$B15) -> 5
B16: Display | C16: 1 | D16: =COUNTIF(Inventory!$C$2:$C$381,$B16) -> 4
B17: Driver | C17: 1 | D17: =COUNTIF(Inventory!$C$2:$C$381,$B17) -> 1
... B48: Wire | C48: 2 | D48: =COUNTIF(Inventory!$C$2:$C$381,$B48) -> 4

Sheet Inventory
A1: ID | B1: Component | C1: Category | D1: SMD | E1: Location | F1: Stock Qty | G1: Issued Out | H1: Available | I1: Min | J1: Status | K1: Last Updated
A2: EC001 | B2: 330 Ω Resistor+ | C2: Resistor | E2: A1 | F2: 10 | G2: =SUMIFS('Issue Log'!$G$2:$G$501,'Issue Log'!$B$2:$B$501,$A2,'Issue Log'!$J$2:$J$501,"Out") -> 0 | H2: =IF($F2="","",$F2-$G2) -> 10 | I2: 10 | J2: =IF($F2="","Not counted",IF($H2<=0,"Out of stock",IF($H2<$I2,"Low stock","In stock"))) -> In stock | K2: Imported 09-Sep-2026 | M2: =IF(Search!$C$4="",0,IF(ISNUMBER(SEARCH(Search!$C$4,$A2&" "&$B2&" "&$C2&" "&$E2)),1,0)) -> 1 | N2: =IF(M2=1,SUM($M$2:M2),"") -> 1 | O2: =IF(OR($J2="Out of stock",$J2="Low stock",$J2="Not counted"),1,0) -> 0 | P2: =IF(O2=1,SUM($O$2:O2),"")
A3: EC002 | B3: 70 Ω Resistor+ | C3: Resistor | E3: A1 | F3: 5 | G3: =SUMIFS('Issue Log'!$G$2:$G$501,'Issue Log'!$B$2:$B$501,$A3,'Issue Log'!$J$2:$J$501,"Out") -> 0 | H3: =IF($F3="","",$F3-$G3) -> 5 | I3: 10 | J3: =IF($F3="","Not counted",IF($H3<=0,"Out of stock",IF($H3<$I3,"Low stock","In stock"))) -> Low stock | K3: Imported 09-Sep-2026 | M3: =IF(Search!$C$4="",0,IF(ISNUMBER(SEARCH(Search!$C$4,$A3&" "&$B3&" "&$C3&" "&$E3)),1,0)) -> 1 | N3: =IF(M3=1,SUM($M$2:M3),"") -> 2 | O3: =IF(OR($J3="Out of stock",$J3="Low stock",$J3="Not counted"),1,0) -> 1 | P3: =IF(O3=1,SUM($O$2:O3),"") -> 1
A4: EC003 | B4: 68 Ω Resistor+ | C4: Resistor | E4: A1 | F4: 150 | G4: =SUMIFS('Issue Log'!$G$2:$G$501,'Issue Log'!$B$2:$B$501,$A4,'Issue Log'!$J$2:$J$501,"Out") -> 0 | H4: =IF($F4="","",$F4-$G4) -> 150 | I4: 10 | J4: =IF($F4="","Not counted",IF($H4<=0,"Out of stock",IF($H4<$I4,"Low stock","In stock"))) -> In stock | K4: Imported 09-Sep-2026 | M4: =IF(Search!$C$4="",0,IF(ISNUMBER(SEARCH(Search!$C$4,$A4&" "&$B4&" "&$C4&" "&$E4)),1,0)) -> 1 | N4: =IF(M4=1,SUM($M$2:M4),"") -> 3 | O4: =IF(OR($J4="Out of stock",$J4="Low stock",$J4="Not counted"),1,0) -> 0 | P4: =IF(O4=1,SUM($O$2:O4),"")
A5: EC004 | B5: 100 Ω Resistor+ | C5: Resistor | E5: A1 | F5: 25 | G5: =SUMIFS('Issue Log'!$G$2:$G$501,'Issue Log'!$B$2:$B$501,$A5,'Issue Log'!$J$2:$J$501,"Out") -> 0 | H5: =IF($F5="","",$F5-$G5) -> 25 | I5: 10 | J5: =IF($F5="","Not counted",IF($H5<=0,"Out of stock",IF($H5<$I5,"Low stock","In stock"))) -> In stock | K5: Imported 09-Sep-2026 | M5: =IF(Search!$C$4="",0,IF(ISNUMBER(SEARCH(Search!$C$4,$A5&" "&$B5&" "&$C5&" "&$E5)),1,0)) -> 1 | N5: =IF(M5=1,SUM($M$2:M5),"") -> 4 | O5: =IF(OR($J5="Out of stock",$J5="Low stock",$J5="Not counted"),1,0) -> 0 | P5: =IF(O5=1,SUM($O$2:O5),"")
A6: EC005 | B6: 5.2 Ω Resistor+ | C6: Resistor | E6: A1 | F6: 20 | G6: =SUMIFS('Issue Log'!$G$2:$G$501,'Issue Log'!$B$2:$B$501,$A6,'Issue Log'!$J$2:$J$501,"Out") -> 0 | H6: =IF($F6="","",$F6-$G6) -> 20 | I6: 10 | J6: =IF($F6="","Not counted",IF($H6<=0,"Out of stock",IF($H6<$I6,"Low stock","In stock"))) -> In stock | K6: Imported 09-Sep-2026 | M6: =IF(Search!$C$4="",0,IF(ISNUMBER(SEARCH(Search!$C$4,$A6&" "&$B6&" "&$C6&" "&$E6)),1,0)) -> 1 | N6: =IF(M6=1,SUM($M$2:M6),"") -> 5 | O6: =IF(OR($J6="Out of stock",$J6="Low stock",$J6="Not counted"),1,0) -> 0 | P6: =IF(O6=1,SUM($O$2:O6),"")
A7: EC006 | B7: 150K Ω Resistor+ | C7: Resistor | E7: A1 | F7: 10 | G7: =SUMIFS('Issue Log'!$G$2:$G$501,'Issue Log'!$B$2:$B$501,$A7,'Issue Log'!$J$2:$J$501,"Out") -> 0 | H7: =IF($F7="","",$F7-$G7) -> 10 | I7: 10 | J7: =IF($F7="","Not counted",IF($H7<=0,"Out of stock",IF($H7<$I7,"Low stock","In stock"))) -> In stock | K7: Imported 09-Sep-2026 | M7: =IF(Search!$C$4="",0,IF(ISNUMBER(SEARCH(Search!$C$4,$A7&" "&$B7&" "&$C7&" "&$E7)),1,0)) -> 1 | N7: =IF(M7=1,SUM($M$2:M7),"") -> 6 | O7: =IF(OR($J7="Out of stock",$J7="Low stock",$J7="Not counted"),1,0) -> 0 | P7: =IF(O7=1,SUM($O$2:O7),"")
A8: EC007 | B8: 15K Ω Resistor+ | C8: Resistor | E8: A1 | F8: 15 | G8: =SUMIFS('Issue Log'!$G$2:$G$501,'Issue Log'!$B$2:$B$501,$A8,'Issue Log'!$J$2:$J$501,"Out") -> 0 | H8: =IF($F8="","",$F8-$G8) -> 15 | I8: 10 | J8: =IF($F8="","Not counted",IF($H8<=0,"Out of stock",IF($H8<$I8,"Low stock","In stock"))) -> In stock | K8: Imported 09-Sep-2026 | M8: =IF(Search!$C$4="",0,IF(ISNUMBER(SEARCH(Search!$C$4,$A8&" "&$B8&" "&$C8&" "&$E8)),1,0)) -> 1 | N8: =IF(M8=1,SUM($M$2:M8),"") -> 7 | O8: =IF(OR($J8="Out of stock",$J8="Low stock",$J8="Not counted"),1,0) -> 0 | P8: =IF(O8=1,SUM($O$2:O8),"")
A9: EC008 | B9: 220 Ω Resistor+ | C9: Resistor | E9: A2 | F9: 50 | G9: =SUMIFS('Issue Log'!$G$2:$G$501,'Issue Log'!$B$2:$B$501,$A9,'Issue Log'!$J$2:$J$501,"Out") -> 0 | H9: =IF($F9="","",$F9-$G9) -> 50 | I9: 10 | J9: =IF($F9="","Not counted",IF($H9<=0,"Out of stock",IF($H9<$I9,"Low stock","In stock"))) -> In stock | K9: Imported 09-Sep-2026 | M9: =IF(Search!$C$4="",0,IF(ISNUMBER(SEARCH(Search!$C$4,$A9&" "&$B9&" "&$C9&" "&$E9)),1,0)) -> 1 | N9: =IF(M9=1,SUM($M$2:M9),"") -> 8 | O9: =IF(OR($J9="Out of stock",$J9="Low stock",$J9="Not counted"),1,0) -> 0 | P9: =IF(O9=1,SUM($O$2:O9),"")
A10: EC009 | B10: 10K Ω Resistor+ | C10: Resistor | E10: A2 | F10: 50 | G10: =SUMIFS('Issue Log'!$G$2:$G$501,'Issue Log'!$B$2:$B$501,$A10,'Issue Log'!$J$2:$J$501,"Out") -> 0 | H10: =IF($F10="","",$F10-$G10) -> 50 | I10: 10 | J10: =IF($F10="","Not counted",IF($H10<=0,"Out of stock",IF($H10<$I10,"Low stock","In stock"))) -> In stock | K10: Imported 09-Sep-2026 | M10: =IF(Search!$C$4="",0,IF(ISNUMBER(SEARCH(Search!$C$4,$A10&" "&$B10&" "&$C10&" "&$E10)),1,0)) -> 1 | N10: =IF(M10=1,SUM($M$2:M10),"") -> 9 | O10: =IF(OR($J10="Out of stock",$J10="Low stock",$J10="Not counted"),1,0) -> 0 | P10: =IF(O10=1,SUM($O$2:O10),"")
A11: EC010 | B11: 330K Ω Resistor+ | C11: Resistor | E11: A2 | F11: 25 | G11: =SUMIFS('Issue Log'!$G$2:$G$501,'Issue Log'!$B$2:$B$501,$A11,'Issue Log'!$J$2:$J$501,"Out") -> 0 | H11: =IF($F11="","",$F11-$G11) -> 25 | I11: 10 | J11: =IF($F11="","Not counted",IF($H11<=0,"Out of stock",IF($H11<$I11,"Low stock","In stock"))) -> In stock | K11: Imported 09-Sep-2026 | M11: =IF(Search!$C$4="",0,IF(ISNUMBER(SEARCH(Search!$C$4,$A11&" "&$B11&" "&$C11&" "&$E11)),1,0)) -> 1 | N11: =IF(M11=1,SUM($M$2:M11),"") -> 10 | O11: =IF(OR($J11="Out of stock",$J11="Low stock",$J11="Not counted"),1,0) -> 0 | P11: =IF(O11=1,SUM($O$2:O11),"")
A12: EC011 | B12: 470 Ω Resistor+ | C12: Resistor | E12: A2 | F12: 10 | G12: =SUMIFS('Issue Log'!$G$2:$G$501,'Issue Log'!$B$2:$B$501,$A12,'Issue Log'!$J$2:$J$501,"Out") -> 0 | H12: =IF($F12="","",$F12-$G12) -> 10 | I12: 10 | J12: =IF($F12="","Not counted",IF($H12<=0,"Out of stock",IF($H12<$I12,"Low stock","In stock"))) -> In stock | K12: Imported 09-Sep-2026 | M12: =IF(Search!$C$4="",0,IF(ISNUMBER(SEARCH(Search!$C$4,$A12&" "&$B12&" "&$C12&" "&$E12)),1,0)) -> 1 | N12: =IF(M12=1,SUM($M$2:M12),"") -> 11 | O12: =IF(OR($J12="Out of stock",$J12="Low stock",$J12="Not counted"),1,0) -> 0 | P12: =IF(O12=1,SUM($O$2:O12),"")
A13: EC012 | B13: 4.7K Ω Resistor+ | C13: Resistor | E13: A2 | F13: 30 | G13: =SUMIFS('Issue Log'!$G$2:$G$501,'Issue Log'!$B$2:$B$501,$A13,'Issue Log'!$J$2:$J$501,"Out") -> 0 | H13: =IF($F13="","",$F13-$G13) -> 30 | I13: 10 | J13: =IF($F13="","Not counted",IF($H13<=0,"Out of stock",IF($H13<$I13,"Low stock","In stock"))) -> In stock | K13: Imported 09-Sep-2026 | M13: =IF(Search!$C$4="",0,IF(ISNUMBER(SEARCH(Search!$C$4,$A13&" "&$B13&" "&$C13&" "&$E13)),1,0)) -> 1 | N13: =IF(M13=1,SUM($M$2:M13),"") -> 12 | O13: =IF(OR($J13="Out of stock",$J13="Low stock",$J13="Not counted"),1,0) -> 0 | P13: =IF(O13=1,SUM($O$2:O13),"")
... A24: EC023 | B24: Adafruit PDM MEMS | C24: Microphone | E24: A4 | F24: 5 | G24: =SUMIFS('Issue Log'!$G$2:$G$501,'Issue Log'!$B$2:$B$501,$A24,'Issue Log'!$J$2:$J$501,"Out") -> 0 | H24: =IF($F24="","",$F24-$G24) -> 5 | I24: 2 | J24: =IF($F24="","Not counted",IF($H24<=0,"Out of stock",IF($H24<$I24,"Low stock","In stock"))) -> In stock | K24: Imported 09-Sep-2026 | M24: =IF(Search!$C$4="",0,IF(ISNUMBER(SEARCH(Search!$C$4,$A24&" "&$B24&" "&$C24&" "&$E24)),1,0)) -> 0 | N24: =IF(M24=1,SUM($M$2:M24),"") | O24: =IF(OR($J24="Out of stock",$J24="Low stock",$J24="Not counted"),1,0) -> 0 | P24: =IF(O24=1,SUM($O$2:O24),"")
A25: EC024 | B25: Microphone and Microphone Module | C25: Microphone | E25: A4 | G25: =SUMIFS('Issue Log'!$G$2:$G$501,'Issue Log'!$B$2:$B$501,$A25,'Issue Log'!$J$2:$J$501,"Out") -> 0 | H25: =IF($F25="","",$F25-$G25) | I25: 2 | J25: =IF($F25="","Not counted",IF($H25<=0,"Out of stock",IF($H25<$I25,"Low stock","In stock"))) -> Not counted | K25: Imported 09-Sep-2026 | M25: =IF(Search!$C$4="",0,IF(ISNUMBER(SEARCH(Search!$C$4,$A25&" "&$B25&" "&$C25&" "&$E25)),1,0)) -> 0 | N25: =IF(M25=1,SUM($M$2:M25),"") | O25: =IF(OR($J25="Out of stock",$J25="Low stock",$J25="Not counted"),1,0) -> 1 | P25: =IF(O25=1,SUM($O$2:O25),"") -> 4
A26: EC025 | B26: Speacker Speacker Module | C26: Speaker | E26: A4 | G26: =SUMIFS('Issue Log'!$G$2:$G$501,'Issue Log'!$B$2:$B$501,$A26,'Issue Log'!$J$2:$J$501,"Out") -> 0 | H26: =IF($F26="","",$F26-$G26) | I26: 1 | J26: =IF($F26="","Not counted",IF($H26<=0,"Out of stock",IF($H26<$I26,"Low stock","In stock"))) -> Not counted | K26: Imported 09-Sep-2026 | M26: =IF(Search!$C$4="",0,IF(ISNUMBER(SEARCH(Search!$C$4,$A26&" "&$B26&" "&$C26&" "&$E26)),1,0)) -> 0 | N26: =IF(M26=1,SUM($M$2:M26),"") | O26: =IF(OR($J26="Out of stock",$J26="Low stock",$J26="Not counted"),1,0) -> 1 | P26: =IF(O26=1,SUM($O$2:O26),"") -> 5
A27: EC026 | B27: 1uf 63V capacitor | C27: Capacitor | E27: A5 | F27: 44 | G27: =SUMIFS('Issue Log'!$G$2:$G$501,'Issue Log'!$B$2:$B$501,$A27,'Issue Log'!$J$2:$J$501,"Out") -> 0 | H27: =IF($F27="","",$F27-$G27) -> 44 | I27: 10 | J27: =IF($F27="","Not counted",IF($H27<=0,"Out of stock",IF($H27<$I27,"Low stock","In stock"))) -> In stock | K27: Imported 09-Sep-2026 | M27: =IF(Search!$C$4="",0,IF(ISNUMBER(SEARCH(Search!$C$4,$A27&" "&$B27&" "&$C27&" "&$E27)),1,0)) -> 0 | N27: =IF(M27=1,SUM($M$2:M27),"") | O27: =IF(OR($J27="Out of stock",$J27="Low stock",$J27="Not counted"),1,0) -> 0 | P27: =IF(O27=1,SUM($O$2:O27),"")
A28: EC027 | B28: 104 Non Polarised Capacitor | C28: Capacitor | E28: A5 | F28: 147 | G28: =SUMIFS('Issue Log'!$G$2:$G$501,'Issue Log'!$B$2:$B$501,$A28,'Issue Log'!$J$2:$J$501,"Out") -> 0 | H28: =IF($F28="","",$F28-$G28) -> 147 | I28: 10 | J28: =IF($F28="","Not counted",IF($H28<=0,"Out of stock",IF($H28<$I28,"Low stock","In stock"))) -> In stock | K28: Imported 09-Sep-2026 | M28: =IF(Search!$C$4="",0,IF(ISNUMBER(SEARCH(Search!$C$4,$A28&" "&$B28&" "&$C28&" "&$E28)),1,0)) -> 0 | N28: =IF(M28=1,SUM($M$2:M28),"") | O28: =IF(OR($J28="Out of stock",$J28="Low stock",$J28="Not counted"),1,0) -> 0 | P28: =IF(O28=1,SUM($O$2:O28),"")
A29: EC028 | B29: 150 Non Polarised Capacitor | C29: Capacitor | E29: A5 | F29: 77 | G29: =SUMIFS('Issue Log'!$G$2:$G$501,'Issue Log'!$B$2:$B$501,$A29,'Issue Log'!$J$2:$J$501,"Out") -> 0 | H29: =IF($F29="","",$F29-$G29) -> 77 | I29: 10 | J29: =IF($F29="","Not counted",IF($H29<=0,"Out of stock",IF($H29<$I29,"Low stock","In stock"))) -> In stock | K29: Imported 09-Sep-2026 | M29: =IF(Search!$C$4="",0,IF(ISNUMBER(SEARCH(Search!$C$4,$A29&" "&$B29&" "&$C29&" "&$E29)),1,0)) -> 0 | N29: =IF(M29=1,SUM($M$2:M29),"") | O29: =IF(OR($J29="Out of stock",$J29="Low stock",$J29="Not counted"),1,0) -> 0 | P29: =IF(O29=1,SUM($O$2:O29),"")
A30: EC029 | B30: 103 Non Polarised Capacitor | C30: Capacitor | E30: A5 | F30: 24 | G30: =SUMIFS('Issue Log'!$G$2:$G$501,'Issue Log'!$B$2:$B$501,$A30,'Issue Log'!$J$2:$J$501,"Out") -> 0 | H30: =IF($F30="","",$F30-$G30) -> 24 | I30: 10 | J30: =IF($F30="","Not counted",IF($H30<=0,"Out of stock",IF($H30<$I30,"Low stock","In stock"))) -> In stock | K30: Imported 09-Sep-2026 | M30: =IF(Search!$C$4="",0,IF(ISNUMBER(SEARCH(Search!$C$4,$A30&" "&$B30&" "&$C30&" "&$E30)),1,0)) -> 0 | N30: =IF(M30=1,SUM($M$2:M30),"") | O30: =IF(OR($J30="Out of stock",$J30="Low stock",$J30="Not counted"),1,0) -> 0 | P30: =IF(O30=1,SUM($O$2:O30),"")
A31: EC030 | B31: 33 Non Polarised Capacitor | C31: Capacitor | E31: A5 | F31: 39 | G31: =SUMIFS('Issue Log'!$G$2:$G$501,'Issue Log'!$B$2:$B$501,$A31,'Issue Log'!$J$2:$J$501,"Out") -> 0 | H31: =IF($F31="","",$F31-$G31) -> 39 | I31: 10 | J31: =IF($F31="","Not counted",IF($H31<=0,"Out of stock",IF($H31<$I31,"Low stock","In stock"))) -> In stock | K31: Imported 09-Sep-2026 | M31: =IF(Search!$C$4="",0,IF(ISNUMBER(SEARCH(Search!$C$4,$A31&" "&$B31&" "&$C31&" "&$E31)),1,0)) -> 0 | N31: =IF(M31=1,SUM($M$2:M31),"") | O31: =IF(OR($J31="Out of stock",$J31="Low stock",$J31="Not counted"),1,0) -> 0 | P31: =IF(O31=1,SUM($O$2:O31),"")
A32: EC031 | B32: 0.1uf 50v Capacitor | C32: Capacitor | E32: A5 | F32: 15 | G32: =SUMIFS('Issue Log'!$G$2:$G$501,'Issue Log'!$B$2:$B$501,$A32,'Issue Log'!$J$2:$J$501,"Out") -> 0 | H32: =IF($F32="","",$F32-$G32) -> 15 | I32: 10 | J32: =IF($F32="","Not counted",IF($H32<=0,"Out of stock",IF($H32<$I32,"Low stock","In stock"))) -> In stock | K32: Imported 09-Sep-2026 | M32: =IF(Search!$C$4="",0,IF(ISNUMBER(SEARCH(Search!$C$4,$A32&" "&$B32&" "&$C32&" "&$E32)),1,0)) -> 0 | N32: =IF(M32=1,SUM($M$2:M32),"") | O32: =IF(OR($J32="Out of stock",$J32="Low stock",$J32="Not counted"),1,0) -> 0 | P32: =IF(O32=1,SUM($O$2:O32),"")
A33: EC032 | B33: 203 Non Polarised Capacitor | C33: Capacitor | E33: A5 | F33: 83 | G33: =SUMIFS('Issue Log'!$G$2:$G$501,'Issue Log'!$B$2:$B$501,$A33,'Issue Log'!$J$2:$J$501,"Out") -> 0 | H33: =IF($F33="","",$F33-$G33) -> 83 | I33: 10 | J33: =IF($F33="","Not counted",IF($H33<=0,"Out of stock",IF($H33<$I33,"Low stock","In stock"))) -> In stock | K33: Imported 09-Sep-2026 | M33: =IF(Search!$C$4="",0,IF(ISNUMBER(SEARCH(Search!$C$4,$A33&" "&$B33&" "&$C33&" "&$E33)),1,0)) -> 0 | N33: =IF(M33=1,SUM($M$2:M33),"") | O33: =IF(OR($J33="Out of stock",$J33="Low stock",$J33="Not counted"),1,0) -> 0 | P33: =IF(O33=1,SUM($O$2:O33),"")
A34: EC033 | B34: 102 Non Polarised Capacitor | C34: Capacitor | E34: A5 | F34: 11 | G34: =SUMIFS('Issue Log'!$G$2:$G$501,'Issue Log'!$B$2:$B$501,$A34,'Issue Log'!$J$2:$J$501,"Out") -> 0 | H34: =IF($F34="","",$F34-$G34) -> 11 | I34: 10 | J34: =IF($F34="","Not counted",IF($H34<=0,"Out of stock",IF($H34<$I34,"Low stock","In stock"))) -> In stock | K34: Imported 09-Sep-2026 | M34: =IF(Search!$C$4="",0,IF(ISNUMBER(SEARCH(Search!$C$4,$A34&" "&$B34&" "&$C34&" "&$E34)),1,0)) -> 0 | N34: =IF(M34=1,SUM($M$2:M34),"") | O34: =IF(OR($J34="Out of stock",$J34="Low stock",$J34="Not counted"),1,0) -> 0 | P34: =IF(O34=1,SUM($O$2:O34),"")
A35: EC034 | B35: 2.7 Non polarised Capacitor | C35: Capacitor | E35: A5 | F35: 6 | G35: =SUMIFS('Issue Log'!$G$2:$G$501,'Issue Log'!$B$2:$B$501,$A35,'Issue Log'!$J$2:$J$501,"Out") -> 0 | H35: =IF($F35="","",$F35-$G35) -> 6 | I35: 10 | J35: =IF($F35="","Not counted",IF($H35<=0,"Out of stock",IF($H35<$I35,"Low stock","In stock"))) -> Low stock | K35: Imported 09-Sep-2026 | M35: =IF(Search!$C$4="",0,IF(ISNUMBER(SEARCH(Search!$C$4,$A35&" "&$B35&" "&$C35&" "&$E35)),1,0)) -> 0 | N35: =IF(M35=1,SUM($M$2:M35),"") | O35: =IF(OR($J35="Out of stock",$J35="Low stock",$J35="Not counted"),1,0) -> 1 | P35: =IF(O35=1,SUM($O$2:O35),"") -> 6
A36: EC035 | B36: 47 Non polarised Capacitor | C36: Capacitor | E36: A5 | F36: 6 | G36: =SUMIFS('Issue Log'!$G$2:$G$501,'Issue Log'!$B$2:$B$501,$A36,'Issue Log'!$J$2:$J$501,"Out") -> 0 | H36: =IF($F36="","",$F36-$G36) -> 6 | I36: 10 | J36: =IF($F36="","Not counted",IF($H36<=0,"Out of stock",IF($H36<$I36,"Low stock","In stock"))) -> Low stock | K36: Imported 09-Sep-2026 | M36: =IF(Search!$C$4="",0,IF(ISNUMBER(SEARCH(Search!$C$4,$A36&" "&$B36&" "&$C36&" "&$E36)),1,0)) -> 0 | N36: =IF(M36=1,SUM($M$2:M36),"") | O36: =IF(OR($J36="Out of stock",$J36="Low stock",$J36="Not counted"),1,0) -> 1 | P36: =IF(O36=1,SUM($O$2:O36),"") -> 7
A37: EC036 | B37: 56 Non Polarised Capacitor | C37: Capacitor | E37: A5 | F37: 8 | G37: =SUMIFS('Issue Log'!$G$2:$G$501,'Issue Log'!$B$2:$B$501,$A37,'Issue Log'!$J$2:$J$501,"Out") -> 0 | H37: =IF($F37="","",$F37-$G37) -> 8 | I37: 10 | J37: =IF($F37="","Not counted",IF($H37<=0,"Out of stock",IF($H37<$I37,"Low stock","In stock"))) -> Low stock | K37: Imported 09-Sep-2026 | M37: =IF(Search!$C$4="",0,IF(ISNUMBER(SEARCH(Search!$C$4,$A37&" "&$B37&" "&$C37&" "&$E37)),1,0)) -> 0 | N37: =IF(M37=1,SUM($M$2:M37),"") | O37: =IF(OR($J37="Out of stock",$J37="Low stock",$J37="Not counted"),1,0) -> 1 | P37: =IF(O37=1,SUM($O$2:O37),"") -> 8
A38: EC037 | B38: 1K 63 Voltage Filter | C38: Filter | E38: A5 | F38: 9 | G38: =SUMIFS('Issue Log'!$G$2:$G$501,'Issue Log'!$B$2:$B$501,$A38,'Issue Log'!$J$2:$J$501,"Out") -> 0 | H38: =IF($F38="","",$F38-$G38) -> 9 | I38: 4 | J38: =IF($F38="","Not counted",IF($H38<=0,"Out of stock",IF($H38<$I38,"Low stock","In stock"))) -> In stock | K38: Imported 09-Sep-2026 | M38: =IF(Search!$C$4="",0,IF(ISNUMBER(SEARCH(Search!$C$4,$A38&" "&$B38&" "&$C38&" "&$E38)),1,0)) -> 0 | N38: =IF(M38=1,SUM($M$2:M38),"") | O38: =IF(OR($J38="Out of stock",$J38="Low stock",$J38="Not counted"),1,0) -> 0 | P38: =IF(O38=1,SUM($O$2:O38),"")
... A101: EC100 | B101: Slide Switch | C101: Switch | E101: C1 | F101: 18 | G101: =SUMIFS('Issue Log'!$G$2:$G$501,'Issue Log'!$B$2:$B$501,$A101,'Issue Log'!$J$2:$J$501,"Out") -> 0 | H101: =IF($F101="","",$F101-$G101) -> 18 | I101: 4 | J101: =IF($F101="","Not counted",IF($H101<=0,"Out of stock",IF($H101<$I101,"Low stock","In stock"))) -> In stock | K101: Imported 09-Sep-2026 | M101: =IF(Search!$C$4="",0,IF(ISNUMBER(SEARCH(Search!$C$4,$A101&" "&$B101&" "&$C101&" "&$E101)),1,0)) -> 0 | N101: =IF(M101=1,SUM($M$2:M101),"") | O101: =IF(OR($J101="Out of stock",$J101="Low stock",$J101="Not counted"),1,0) -> 0 | P101: =IF(O101=1,SUM($O$2:O101),"")
A102: EC101 | B102: Push Switch | C102: Switch | E102: C1 | G102: =SUMIFS('Issue Log'!$G$2:$G$501,'Issue Log'!$B$2:$B$501,$A102,'Issue Log'!$J$2:$J$501,"Out") -> 0 | H102: =IF($F102="","",$F102-$G102) | I102: 4 | J102: =IF($F102="","Not counted",IF($H102<=0,"Out of stock",IF($H102<$I102,"Low stock","In stock"))) -> Not counted | K102: Imported 09-Sep-2026 | M102: =IF(Search!$C$4="",0,IF(ISNUMBER(SEARCH(Search!$C$4,$A102&" "&$B102&" "&$C102&" "&$E102)),1,0)) -> 0 | N102: =IF(M102=1,SUM($M$2:M102),"") | O102: =IF(OR($J102="Out of stock",$J102="Low stock",$J102="Not counted"),1,0) -> 1 | P102: =IF(O102=1,SUM($O$2:O102),"") -> 14
A103: EC102 | B103: 18 Pin IC Base | C103: IC Base | E103: C2 | F103: 51 | G103: =SUMIFS('Issue Log'!$G$2:$G$501,'Issue Log'!$B$2:$B$501,$A103,'Issue Log'!$J$2:$J$501,"Out") -> 0 | H103: =IF($F103="","",$F103-$G103) -> 51 | I103: 5 | J103: =IF($F103="","Not counted",IF($H103<=0,"Out of stock",IF($H103<$I103,"Low stock","In stock"))) -> In stock | K103: Imported 09-Sep-2026 | M103: =IF(Search!$C$4="",0,IF(ISNUMBER(SEARCH(Search!$C$4,$A103&" "&$B103&" "&$C103&" "&$E103)),1,0)) -> 0 | N103: =IF(M103=1,SUM($M$2:M103),"") | O103: =IF(OR($J103="Out of stock",$J103="Low stock",$J103="Not counted"),1,0) -> 0 | P103: =IF(O103=1,SUM($O$2:O103),"")
A104: EC103 | B104: 14 Pin IC Base | C104: IC Base | E104: C2 | F104: 188 | G104: =SUMIFS('Issue Log'!$G$2:$G$501,'Issue Log'!$B$2:$B$501,$A104,'Issue Log'!$J$2:$J$501,"Out") -> 0 | H104: =IF($F104="","",$F104-$G104) -> 188 | I104: 5 | J104: =IF($F104="","Not counted",IF($H104<=0,"Out of stock",IF($H104<$I104,"Low stock","In stock"))) -> In stock | K104: Imported 09-Sep-2026 | M104: =IF(Search!$C$4="",0,IF(ISNUMBER(SEARCH(Search!$C$4,$A104&" "&$B104&" "&$C104&" "&$E104)),1,0)) -> 0 | N104: =IF(M104=1,SUM($M$2:M104),"") | O104: =IF(OR($J104="Out of stock",$J104="Low stock",$J104="Not counted"),1,0) -> 0 | P104: =IF(O104=1,SUM($O$2:O104),"")
A105: EC104 | B105: 20 Pin IC Base | C105: IC Base | E105: C2 | F105: 144 | G105: =SUMIFS('Issue Log'!$G$2:$G$501,'Issue Log'!$B$2:$B$501,$A105,'Issue Log'!$J$2:$J$501,"Out") -> 0 | H105: =IF($F105="","",$F105-$G105) -> 144 | I105: 5 | J105: =IF($F105="","Not counted",IF($H105<=0,"Out of stock",IF($H105<$I105,"Low stock","In stock"))) -> In stock | K105: Imported 09-Sep-2026 | M105: =IF(Search!$C$4="",0,IF(ISNUMBER(SEARCH(Search!$C$4,$A105&" "&$B105&" "&$C105&" "&$E105)),1,0)) -> 0 | N105: =IF(M105=1,SUM($M$2:M105),"") | O105: =IF(OR($J105="Out of stock",$J105="Low stock",$J105="Not counted"),1,0) -> 0 | P105: =IF(O105=1,SUM($O$2:O105),"")
A106: EC105 | B106: 24V Relay | C106: Relay | E106: C3 | F106: 10 | G106: =SUMIFS('Issue Log'!$G$2:$G$501,'Issue Log'!$B$2:$B$501,$A106,'Issue Log'!$J$2:$J$501,"Out") -> 0 | H106: =IF($F106="","",$F106-$G106) -> 10 | I106: 2 | J106: =IF($F106="","Not counted",IF($H106<=0,"Out of stock",IF($H106<$I106,"Low stock","In stock"))) -> In stock | K106: Imported 09-Sep-2026 | M106: =IF(Search!$C$4="",0,IF(ISNUMBER(SEARCH(Search!$C$4,$A106&" "&$B106&" "&$C106&" "&$E106)),1,0)) -> 0 | N106: =IF(M106=1,SUM($M$2:M106),"") | O106: =IF(OR($J106="Out of stock",$J106="Low stock",$J106="Not counted"),1,0) -> 0 | P106: =IF(O106=1,SUM($O$2:O106),"")
A107: EC106 | B107: 5V Realy | C107: Relay | E107: C3 | F107: 20 | G107: =SUMIFS('Issue Log'!$G$2:$G$501,'Issue Log'!$B$2:$B$501,$A107,'Issue Log'!$J$2:$J$501,"Out") -> 0 | H107: =IF($F107="","",$F107-$G107) -> 20 | I107: 2 | J107: =IF($F107="","Not counted",IF($H107<=0,"Out of stock",IF($H107<$I107,"Low stock","In stock"))) -> In stock | K107: Imported 09-Sep-2026 | M107: =IF(Search!$C$4="",0,IF(ISNUMBER(SEARCH(Search!$C$4,$A107&" "&$B107&" "&$C107&" "&$E107)),1,0)) -> 0 | N107: =IF(M107=1,SUM($M$2:M107),"") | O107: =IF(OR($J107="Out of stock",$J107="Low stock",$J107="Not counted"),1,0) -> 0 | P107: =IF(O107=1,SUM($O$2:O107),"")
A108: EC107 | B108: L298N Module | C108: Module | E108: C3 | F108: 5 | G108: =SUMIFS('Issue Log'!$G$2:$G$501,'Issue Log'!$B$2:$B$501,$A108,'Issue Log'!$J$2:$J$501,"Out") -> 0 | H108: =IF($F108="","",$F108-$G108) -> 5 | I108: 2 | J108: =IF($F108="","Not counted",IF($H108<=0,"Out of stock",IF($H108<$I108,"Low stock","In stock"))) -> In stock | K108: Imported 09-Sep-2026 | M108: =IF(Search!$C$4="",0,IF(ISNUMBER(SEARCH(Search!$C$4,$A108&" "&$B108&" "&$C108&" "&$E108)),1,0)) -> 0 | N108: =IF(M108=1,SUM($M$2:M108),"") | O108: =IF(OR($J108="Out of stock",$J108="Low stock",$J108="Not counted"),1,0) -> 0 | P108: =IF(O108=1,SUM($O$2:O108),"")
A109: EC108 | B109: 28 Pin IC Base | C109: IC Base | E109: C4 | F109: 6 | G109: =SUMIFS('Issue Log'!$G$2:$G$501,'Issue Log'!$B$2:$B$501,$A109,'Issue Log'!$J$2:$J$501,"Out") -> 0 | H109: =IF($F109="","",$F109-$G109) -> 6 | I109: 5 | J109: =IF($F109="","Not counted",IF($H109<=0,"Out of stock",IF($H109<$I109,"Low stock","In stock"))) -> In stock | K109: Imported 09-Sep-2026 | M109: =IF(Search!$C$4="",0,IF(ISNUMBER(SEARCH(Search!$C$4,$A109&" "&$B109&" "&$C109&" "&$E109)),1,0)) -> 0 | N109: =IF(M109=1,SUM($M$2:M109),"") | O109: =IF(OR($J109="Out of stock",$J109="Low stock",$J109="Not counted"),1,0) -> 0 | P109: =IF(O109=1,SUM($O$2:O109),"")
A110: EC109 | B110: 40 Pin ZIF Socket | C110: IC Base | E110: C4 | F110: 3 | G110: =SUMIFS('Issue Log'!$G$2:$G$501,'Issue Log'!$B$2:$B$501,$A110,'Issue Log'!$J$2:$J$501,"Out") -> 0 | H110: =IF($F110="","",$F110-$G110) -> 3 | I110: 5 | J110: =IF($F110="","Not counted",IF($H110<=0,"Out of stock",IF($H110<$I110,"Low stock","In stock"))) -> Low stock | K110: Imported 09-Sep-2026 | M110: =IF(Search!$C$4="",0,IF(ISNUMBER(SEARCH(Search!$C$4,$A110&" "&$B110&" "&$C110&" "&$E110)),1,0)) -> 0 | N110: =IF(M110=1,SUM($M$2:M110),"") | O110: =IF(OR($J110="Out of stock",$J110="Low stock",$J110="Not counted"),1,0) -> 1 | P110: =IF(O110=1,SUM($O$2:O110),"") -> 15
A111: EC110 | B111: 28 Pin ZIF Socket | C111: IC Base | E111: C4 | F111: 13 | G111: =SUMIFS('Issue Log'!$G$2:$G$501,'Issue Log'!$B$2:$B$501,$A111,'Issue Log'!$J$2:$J$501,"Out") -> 0 | H111: =IF($F111="","",$F111-$G111) -> 13 | I111: 5 | J111: =IF($F111="","Not counted",IF($H111<=0,"Out of stock",IF($H111<$I111,"Low stock","In stock"))) -> In stock | K111: Imported 09-Sep-2026 | M111: =IF(Search!$C$4="",0,IF(ISNUMBER(SEARCH(Search!$C$4,$A111&" "&$B111&" "&$C111&" "&$E111)),1,0)) -> 0 | N111: =IF(M111=1,SUM($M$2:M111),"") | O111: =IF(OR($J111="Out of stock",$J111="Low stock",$J111="Not counted"),1,0) -> 0 | P111: =IF(O111=1,SUM($O$2:O111),"")
A112: EC111 | B112: NEO 6M GPS Module | C112: Module | E112: UNASSIGNED | F112: 15 | G112: =SUMIFS('Issue Log'!$G$2:$G$501,'Issue Log'!$B$2:$B$501,$A112,'Issue Log'!$J$2:$J$501,"Out") -> 0 | H112: =IF($F112="","",$F112-$G112) -> 15 | I112: 2 | J112: =IF($F112="","Not counted",IF($H112<=0,"Out of stock",IF($H112<$I112,"Low stock","In stock"))) -> In stock | K112: Imported 09-Sep-2026 | M112: =IF(Search!$C$4="",0,IF(ISNUMBER(SEARCH(Search!$C$4,$A112&" "&$B112&" "&$C112&" "&$E112)),1,0)) -> 0 | N112: =IF(M112=1,SUM($M$2:M112),"") | O112: =IF(OR($J112="Out of stock",$J112="Low stock",$J112="Not counted"),1,0) -> 0 | P112: =IF(O112=1,SUM($O$2:O112),"")
...

Sheet Notes
B2: ABOUT THIS FILE
B5: Source: EC Lab Eventry Management System.xlsx (Sheet1, rows 2-391), imported 9 September 2026.
B6: 380 components across 58 storage positions were carried over.
B8: Cleaning applied to the original data
B9: • Quantities written as "50+" were read as 50 and the component name carries a trailing + as a reminder.
B10: • Quantities written as "?" were left blank and show as Not counted — 46 items need a physical count.
B11: • Category spellings were unified (RES. / RES → Resistor, CAP. / CAP (SMD) → Capacitor, and so on).
B12: • SMD parts kept their own column instead of being folded into the category name.
B13: • Rows with no location were placed in UNASSIGNED so they stay visible instead of disappearing.
B15: Columns you edit are blue. Everything black is a formula.
B16: Stock Qty the physical count on the shelf
B17: Min the level below which the row turns amber
... B28: export its CSV whenever you want this workbook refreshed.
